Workbook

Sheet Tabelle1
A3: Technisches Datenblatt
A4: Data sheet
K5: Erstellt durch: | L5: BOT
A6: Bezeichnung: Designation: | B6: Getriebemotor: Gear Motor: | C6: KSG 5612.25 HD R4 / 400.0 | K6: Datum: | L6: =TODAY() -> 46050
A8: Kennlinie Getriebemotor: Characteristic Curve of Gear Motor: | K8: Bemessungsspannung, UN (V) | L8: 400
K9: Bemessungsdrehzahl, nN (minˉ¹) | L9: 2000 | M9: =L9/L30 -> 222.22222 | N9: 400
K10: Bemessungsdrehmoment, MN (Nm) | L10: 10.9 | M10: =L10*$L$30*$L$29/100 -> 95.157 | N10: =10.5*L30*L29/100 -> 91.665
K11: Stillstandsmoment M0 (Nm) | L11: 16.9 | M11: =L11*$L$30*$L$29/100 -> 147.537 | N11: =13.1*L30*L29/100 -> 114.363
K12: Spitzenmoment, Mmax (Nm) | L12: 64.2 | M12: =L12*$L$30*$L$29/100 -> 560.466
K13: Bemessungsstrom, IN (A) | L13: 6.8146457
K14: Stillstandsstrom I0 (A) | L14: 10.496894
K15: Spitzenstrom, Imax (A) | L15: 44.6
K16: Spannungskonstante, Ke (V/1000 minˉ¹) | L16: 106.3
K17: Ständerwiederstand, RU-V (Ω) | L17: 0.6
K18: Ständerinduktivität, LU-V (mH) | L18: 3.2
K19: Polzahl | L19: 6
K20: Max. Zulässige Spannung(V) | L20: 679
K21: Rotorträgheitsmoment, JR (kg∙cm²) | L21: 39 | M21: 40
K22: Gewicht, m (kg) | L22: 47.8
K23: Thermische Konstante TTherm (min) | L23: 79
K24: Schutzart | L24: IP69K
K25: Betriebsart | L25: S1
K26: Isolationsklasse | L26: F
A27: Technische Daten: Technical data: | C27: Motor 1 | D27: Getriebemotor 2 Gear motor | F27: Motor 1 | G27: Getriebemotor 2 Gear motor
A28: Bemessungsspannung, UN (V) Rated voltage | C28: =L8 -> 400 | D28: =L8 -> 400 | K28: Getriebe
A29: Bemessungsdrehzahl, nN (minˉ¹) Rated speed | C29: =L9 -> 2000 | D29: =M9 -> 222.22222 | E29: Polzahl Number of poles | F29: =L19 -> 6 | K29: Wirkungsgrad | L29: 97
A30: Bemessungsleistung, PN (kW) Rated power | C30: =(C29*C31*PI()/30)/1000 -> 2.2828907 | D30: =(D29*D31*PI()/30)/1000 -> 2.2144039 | E30: Ständerwiderstand, RU-V (Ω)* Stator resistance | F30: =L17 -> 0.6 | K30: Übersetzung | L30: 9
A31: Bemessungsdrehmoment, MN (Nm) Rated torque | C31: =L10 -> 10.9 | D31: =M10 -> 95.157 | E31: Ständerinduktivität, LU-V (mH) Stator inductance | F31: =L18 -> 3.2 | K31: Not-Aus-Moment | L31: 830
A32: Bemessungsstrom, IN (A) Rated current | C32: =L13 -> 6.8146457 | E32: Elektr. Zeitkonstante, Tel (ms) Electrical time constant | F32: =F31/F30 -> 5.3333333 | K32: Max. Beschleunigungsmoment | L32: 750
A34: Bemessungsdrehmomentkonstante, KTN (Nm/Aeff) Rated torque constant | C34: =C31/C32 -> 1.5994962 | K34: Maximale Drehzahl | L34: 4000
A35: Spannungskonstante, Ke (V/1000 minˉ¹) Voltage constant | C35: =L16 -> 106.3 | E35: Max. zulässige Spannung, U (V) Max. possible voltage | F35: =L20 -> 679 | K35: Umgebungstemperatur | L35: -10 bis/to 25
A37: Stillstandsmoment, MO (Nm) ** Stall torque | C37: =L11 -> 16.9 | D37: =M11 -> 147.537 | E37: Schutzart Degree of protection | F37: =L24 -> IP69K
A38: Stillstandsstrom, IO (A) ** Stall current | C38: =L14 -> 10.496894 | E38: Betriebsart Duty type | F38: =L25 -> S1
A39: Stillstandsdrehmomentkonstante, KTO (Nm/A) Stall torque constant | C39: =C31/C32 -> 1.5994962 | E39: Isolationsklasse Insulation class | F39: =L26 -> F
A41: Spitzenmoment, Mmax (Nm) *** Peak torque | C41: =L12 -> 64.2 | D41: =M12 -> 560.466 | E41: Rotorträgheitsmoment, JR (kg∙cm²) Rotor moment of inertia | F41: =L21 -> 39 | G41: =M21 -> 40
A42: Spitzenstrom, Imax (A) *** Peak current | C42: =L15 -> 44.6 | E42: Gewicht, m (kg) Weight | F42: tbd
A43: Spitzendrehmomentkonstante, KT max (Nm/Aeff) Peak torque constant | C43: =C41/C42 -> 1.4394619 | E43: Thermische Konstante TTherm (min)**** Termal time constant | F43: =L23 -> 79
A44: Zusätzlich Getriebedaten: Additional transmission data: | E44: Umgebungstemperatur (°C) Ambient temperature | F44: =L35 -> -10 bis/to 25
A45: Wirkungsgrad Efficiency | D45: =L29 -> 97 | E45: Rating nach DIN EN 60034 (Rating according to DIN EN 60034) * Werte bei 20°C (Values at 20°C) ** Werte bei 200 minˉ¹ (Values at 200 minˉ¹) *** Kurzzeitbetrieb max. 3s (Short-time operation max. 3s) **** geschätzter Wert (estimated value)
A46: Übersetzung Gear ratio | D46: =L30 -> 9
...

Sheet Tabelle2
B3: Diagrammdaten:
B5: Drehzahl: | C5: M_max bei 0,85*U_n M_max at 0.85*U_n | D5: M_n S1-Betrieb (Erwärmung Wicklung: Δ100K / Gehäuse: Δ80K) M_n S1-Duty (Temp.rise winding: Δ100K / housing: Δ80K) | E5: M_n S1-Betrieb (Erwärmung Wicklung: Δ60K / Gehäuse: Δ40K) M_n S1-Duty (Temp.rise winding: Δ60K / housing: Δ40K)
B6: 0 | C6: =Tabelle1!D41 -> 560.466 | D6: =Tabelle1!D37 -> 147.537 | E6: =Tabelle1!N11 -> 114.363
B7: 100 | E7: =Tabelle1!N10 -> 91.665
B8: =Tabelle1!D29 -> 222.22222 | D8: =Tabelle1!D31 -> 95.157
B9: =(((-1*(-2*C16*0.85*C17))-SQRT(((-2*C16*0.85*C17)^2)-4*(C17^2-C20^2*C19^2*4*(PI())^2*(C21^2/60^2))*((C16*0.85)^2-C20^2*C18^2)))/(2*(C17^2-C20^2*C19^2*4*(PI())^2*(C21^2/60^2))))/Tabelle1!L30 -> 191.46569 | C9: =C6 -> 560.466
B10: =((Tabelle1!D37-(Tabelle1!D41-((Tabelle1!D41*B9)/(B9-B11))))/((Tabelle1!D41/(B9-B11))-((Tabelle1!D31-Tabelle1!D37)/Tabelle1!D29))) -> 396.20834 | C10: =((C6/(Tabelle2!B9-Tabelle2!B11))*Tabelle2!B10+(C6-((C6*Tabelle2!B9)/(Tabelle2!B9-Tabelle2!B11)))) -> 54.146733 | D10: =(((Tabelle1!D31-Tabelle1!D37)/Tabelle1!D29)*Tabelle2!B10+Tabelle1!D37) -> 54.146733
B11: =Tabelle1!C28/Tabelle1!C35*1000/Tabelle1!L30 -> 418.1039 | C11: 0
B14: Berechnungsdaten:
B16: U (V) | C16: =Tabelle1!D28 -> 400 | E16: K_e | F16: =C17*60/2/PI()/1000 -> 0.0010150902 | G16: Vs | H16: Flussverkettung
B17: Ke (V/minˉ¹) | C17: =Tabelle1!C35/1000 -> 0.1063 | E17: Bemessungs-Leiterspannung U_ph,max | F17: =C16/SQRT((3)) -> 230.94011 | G17: V
B18: RU-V (Ω) | C18: =Tabelle1!F30 -> 0.6 | E18: omega_eck | F18: =SQRT(F17^2-(C18*C20)^2)/(F16+C19*C20) -> 1595.8836 | G18: 1/s
B19: LU-V (H) | C19: =Tabelle1!F31/1000 -> 0.0032 | E19: n_eck | F19: =60*F18/2/PI()/C21 -> 2539.9276 | G19: 1/min
B20: Imax (A) | C20: =Tabelle1!L15 -> 44.6 | E20: M_eck | F20: =3*F17*C20/F18 -> 19.362181 | G20: Nm
B21: p | C21: =Tabelle1!L19 -> 6 | E21: P_eck | F21: =F20*F18 -> 30899.786 | G21: W

Sheet Tabelle3
B5: 0.05714 | C5: 0.02408
B6: =B5*B5 -> 0.0032649796 | C6: =C5*C5 -> 0.0005798464 | D6: =SQRT(B6+C6)*1000 -> 62.006661
